Workbook

Sheet План
A1: Контент-план РЕШЕНО — что за чем идёт
A2: Идём сверху вниз. В колонках площадок выберите «Выложено», когда пост вышел. «—» — на этой площадке не публикуем. Пути к файлам — от папки content/week-01_28.09-04.10/, если не указано иначе (папки reels/, brag-output/, youtube/ — в корне репозитория).
A3: № | B3: Блок | C3: Что выкладываем | D3: Формат | E3: Рубрика | F3: Telegram | G3: VK | H3: Instagram | I3: YouTube | J3: TG-чат | K3: Статус | L3: Материал | M3: Где лежит файл | N3: Что сделать перед публикацией | O3: Комментарий
A4: 1 | B4: 1. Запуск | C4: Первое сообщение канала — «визитка» (что это за канал) | D4: Пост | E4: Запуск | F4: Нужно | G4: — | H4: — | I4: — | J4: — | K4: =IF(COUNTIF(F4:J4,"Нужно")=0,"Готово","Осталось: "&COUNTIF(F4:J4,"Нужно")) | L4: Готов | M4: content/week-01_28.09-04.10/telegram/00-pervoe-soobschenie-kanala.md | N4: Опубликовать сразу после создания канала
A5: 2 | B5: 1. Запуск | C5: Манифест «Не просто послушать. Приехать решить.» + закрепить | D5: Пост + картинка | E5: Манифест | F5: Нужно | G5: Нужно | H5: — | I5: — | J5: — | K5: =IF(COUNTIF(F5:J5,"Нужно")=0,"Готово","Осталось: "&COUNTIF(F5:J5,"Нужно")) | L5: Готов | M5: telegram/1-pn-28.09-manifest.md · vk/1-pn-28.09-manifest/cover.png | N5: Подставить ссылку на канал в VK-версии
A6: 3 | B6: 1. Запуск | C6: Рассылка по базе ассоциации со ссылкой на канал | D6: Рассылка | E6: Привлечение | F6: Нужно | G6: — | H6: — | I6: — | J6: — | K6: =IF(COUNTIF(F6:J6,"Нужно")=0,"Готово","Осталось: "&COUNTIF(F6:J6,"Нужно")) | L6: Готов | M6: telegram/0-rassylka-po-baze-associacii.md | N6: От имени Р. А. Прокопьева; вставить ссылку на канал
A7: 4 | B7: 1. Запуск | C7: Карусель «Не просто послушать» (6 слайдов) | D7: Карусель | E7: Манифест | F7: — | G7: Нужно | H7: Нужно | I7: — | J7: — | K7: =IF(COUNTIF(F7:J7,"Нужно")=0,"Готово","Осталось: "&COUNTIF(F7:J7,"Нужно")) | L7: Готов | M7: instagram/1-pn-28.09-karusel-manifest/ (slide-1…6 + podpis.md)
A8: 5 | B8: 1. Запуск | C8: Сторис «Мы запустились» + ссылка на канал | D8: Сторис | E8: Запуск | F8: — | G8: Нужно | H8: Нужно | I8: — | J8: — | K8: =IF(COUNTIF(F8:J8,"Нужно")=0,"Готово","Осталось: "&COUNTIF(F8:J8,"Нужно")) | L8: Готов | M8: instagram/stories/1-pn-28.09-*.png | N8: Добавить стикер-ссылку на канал
A9: 6 | B9: 1. Запуск | C9: Промо-ролик форума (горизонтальный, 23 с) | D9: Видео | E9: Промо | F9: Нужно | G9: Нужно | H9: — | I9: Нужно | J9: — | K9: =IF(COUNTIF(F9:J9,"Нужно")=0,"Готово","Осталось: "&COUNTIF(F9:J9,"Нужно")) | L9: Готов | M9: brag-output/brag.mp4 | N9: В ролике есть дата 13–14 ноября — проверить, что актуально
A10: 7 | B10: 1. Запуск | C10: Дерзкий вертикальный промо «Не ещё одна конференция» | D10: Рилс | E10: Промо | F10: Нужно | G10: Нужно | H10: Нужно | I10: — | J10: — | K10: =IF(COUNTIF(F10:J10,"Нужно")=0,"Готово","Осталось: "&COUNTIF(F10:J10,"Нужно")) | L10: Готов | M10: brag-output/brag-vertical.mp4 | N10: В ролике дата и «стартовая цена для первых 50» — проверить
A11: 8 | B11: 2. Кто мы | C11: Видеообращение Р. А. Прокопьева «Зачем мы делаем РЕШЕНО» | D11: Видео / рилс | E11: Организатор | F11: Нужно | G11: Нужно | H11: Нужно | I11: — | J11: — | K11: =IF(COUNTIF(F11:J11,"Нужно")=0,"Готово","Осталось: "&COUNTIF(F11:J11,"Нужно")) | L11: Нужно снять | M11: Сценарий: instagram/2-vt-29.09-rils-organizator/scenariy.md · обложка там же | N11: Снять 30–45 с вертикально, с субтитрами
A12: 9 | B12: 2. Кто мы | C12: Сторис «Готовим РЕШЕНО» + опрос «Были на форуме, который помог?» | D12: Сторис | E12: Закулисье | F12: — | G12: Нужно | H12: Нужно | I12: — | J12: — | K12: =IF(COUNTIF(F12:J12,"Нужно")=0,"Готово","Осталось: "&COUNTIF(F12:J12,"Нужно")) | L12: Нужно сделать | M12: instagram/stories/2-vt-*.png | N12: Нужно фото команды в рамку
A13: 10 | B13: 3. Атмосфера | C13: Рилс «Полный зал» | D13: Рилс | E13: Атмосфера | F13: Нужно | G13: Нужно | H13: Нужно | I13: — | J13: — | K13: =IF(COUNTIF(F13:J13,"Нужно")=0,"Готово","Осталось: "&COUNTIF(F13:J13,"Нужно")) | L13: Готов | M13: reels/reel1-polnyy-zal.mp4 (без музыки: reels/bez-muzyki/) | N13: Подпись — reels/README.md
A14: 11 | B14: 3. Атмосфера | C14: Рилс «Как это выглядит» — день форума | D14: Рилс | E14: Атмосфера | F14: Нужно | G14: Нужно | H14: Нужно | I14: — | J14: — | K14: =IF(COUNTIF(F14:J14,"Нужно")=0,"Готово","Осталось: "&COUNTIF(F14:J14,"Нужно")) | L14: Готов | M14: reels/reel2-kak-eto-vyglyadit.mp4
A15: 12 | B15: 4. Вопросы бизнеса | C15: Пост «5 вопросов, ради которых стоит приехать» + карточка | D15: Пост + картинка | E15: 5 вопросов | F15: Нужно | G15: Нужно | H15: — | I15: — | J15: — | K15: =IF(COUNTIF(F15:J15,"Нужно")=0,"Готово","Осталось: "&COUNTIF(F15:J15,"Нужно")) | L15: Готов | M15: telegram/3-sr-30.09-5-voprosov.md · vk/3-sr-30.09-5-voprosov/
A16: 13 | B16: 4. Вопросы бизнеса | C16: Карусель «5 вопросов» (7 слайдов) | D16: Карусель | E16: 5 вопросов | F16: — | G16: — | H16: Нужно | I16: — | J16: — | K16: =IF(COUNTIF(F16:J16,"Нужно")=0,"Готово","Осталось: "&COUNTIF(F16:J16,"Нужно")) | L16: Готов | M16: instagram/3-sr-30.09-karusel-5-voprosov/
A17: 14 | B17: 4. Вопросы бизнеса | C17: Сторис со стикером-вопросом «Какой вопрос не даёт покоя?» | D17: Сторис | E17: 5 вопросов | F17: — | G17: Нужно | H17: Нужно | I17: — | J17: — | K17: =IF(COUNTIF(F17:J17,"Нужно")=0,"Готово","Осталось: "&COUNTIF(F17:J17,"Нужно")) | L17: Готов | M17: instagram/stories/3-sr-30.09-vopros.png | N17: Добавить стикер-вопрос
A18: 15 | B18: 4. Вопросы бизнеса | C18: Опрос «Что мешает бизнесу расти?» (5 вариантов) | D18: Опрос | E18: Опрос | F18: Нужно | G18: Нужно | H18: Нужно | I18: — | J18: — | K18: =IF(COUNTIF(F18:J18,"Нужно")=0,"Готово","Осталось: "&COUNTIF(F18:J18,"Нужно")) | L18: Готов | M18: telegram/4-cht-01.10-opros.md · vk/4-cht-01.10-opros/ · stories/4-cht-* | N18: Переслать опрос в чаты ассоциации
A19: 16 | B19: 3. Атмосфера | C19: Рилс «Сцена» — «Минимум сцены. Максимум разбора.» | D19: Рилс | E19: Атмосфера | F19: Нужно | G19: Нужно | H19: Нужно | I19: — | J19: — | K19: =IF(COUNTIF(F19:J19,"Нужно")=0,"Готово","Осталось: "&COUNTIF(F19:J19,"Нужно")) | L19: Готов | M19: reels/reel3-scena.mp4
A20: 17 | B20: 4. Вопросы бизнеса | C20: Вопрос недели: «Спортшкола без CRM — через 3 года всё?» | D20: Пост + рилс | E20: Future | F20: Нужно | G20: Нужно | H20: Нужно | I20: — | J20: — | K20: =IF(COUNTIF(F20:J20,"Нужно")=0,"Готово","Осталось: "&COUNTIF(F20:J20,"Нужно")) | L20: Нужно снять | M20: telegram/5-pt-02.10-vopros-nedeli.md · vk/5-pt-02.10-klip-vopros-nedeli/ (обложка, титры, сценарий) | N20: Снять ролик с человеком в кадре
A21: 18 | B21: 4. Вопросы бизнеса | C21: Итоги опроса — цифры + диаграмма + карусель | D21: Пост + карусель | E21: Опрос | F21: Нужно | G21: Нужно | H21: Нужно | I21: — | J21: — | K21: =IF(COUNTIF(F21:J21,"Нужно")=0,"Готово","Осталось: "&COUNTIF(F21:J21,"Нужно")) | L21: Ждём цифры опроса | M21: telegram/6-sb-03.10-itogi-oprosa.md · vk/6-sb-03.10-itogi-oprosa/ · instagram/6-sb-03.10-karusel-itogi/ | N21: Прислать результаты — перерисую картинки
A22: 19 | B22: 3. Атмосфера | C22: Рилс «Hot Seat» — вопросы из зала | D22: Рилс | E22: Атмосфера | F22: Нужно | G22: Нужно | H22: Нужно | I22: — | J22: — | K22: =IF(COUNTIF(F22:J22,"Нужно")=0,"Готово","Осталось: "&COUNTIF(F22:J22,"Нужно")) | L22: Готов | M22: reels/reel4-hot-seat.mp4
A23: 20 | B23: 5. Форматы | C23: Business Live: «Три бизнеса. Три проблемы. Три решения.» + набор на разбор | D23: Пост + картинка | E23: Business Live | F23: Нужно | G23: Нужно | H23: — | I23: — | J23: — | K23: =IF(COUNTIF(F23:J23,"Нужно")=0,"Готово","Осталось: "&COUNTIF(F23:J23,"Нужно")) | L23: Готов | M23: brag-output/post-business-live.png · текст: brag-output/posts.md (№3)
A24: 21 | B24: 5. Форматы | C24: Карусель «5 вопросов собственнику» с сессиями программы | D24: Карусель | E24: 5 вопросов | F24: — | G24: Нужно | H24: Нужно | I24: — | J24: — | K24: =IF(COUNTIF(F24:J24,"Нужно")=0,"Готово","Осталось: "&COUNTIF(F24:J24,"Нужно")) | L24: Готов | M24: brag-output/carousel/ (slide-1…7) | N24: В подписи есть даты — проверить
A25: 22 | B25: 6. Лёгкое | C25: Мем «Понедельник владельца спортивной школы» | D25: Пост + картинка | E25: Лёгкий | F25: Нужно | G25: Нужно | H25: — | I25: — | J25: — | K25: =IF(COUNTIF(F25:J25,"Нужно")=0,"Готово","Осталось: "&COUNTIF(F25:J25,"Нужно")) | L25: Готов | M25: telegram/7-vs-04.10-mem/
A26: 23 | B26: 6. Лёгкое | C26: Сторис: закулисье + анонс следующей темы | D26: Сторис | E26: Закулисье | F26: — | G26: Нужно | H26: Нужно | I26: — | J26: — | K26: =IF(COUNTIF(F26:J26,"Нужно")=0,"Готово","Осталось: "&COUNTIF(F26:J26,"Нужно")) | L26: Нужно сделать | M26: instagram/stories/7-vs-04.10-anons.png | N26: Нужно фото закулисья в рамку
A27: 24 | B27: 7. Чат | C27: Создать чат и закрепить правила | D27: Чат | E27: Чат | F27: — | G27: — | H27: — | I27: — | J27: Нужно | K27: =IF(COUNTIF(F27:J27,"Нужно")=0,"Готово","Осталось: "&COUNTIF(F27:J27,"Нужно")) | L27: Готов | M27: telegram-chat/1-nastroyka.md · 2-pravila-zakrep.md · 3-opisanie.md
A28: 25 | B28: 7. Чат | C28: Лично пригласить 10–15 человек | D28: Чат | E28: Чат | F28: — | G28: — | H28: — | I28: — | J28: Нужно | K28: =IF(COUNTIF(F28:J28,"Нужно")=0,"Готово","Осталось: "&COUNTIF(F28:J28,"Нужно")) | L28: Нужно сделать | M28: telegram-chat/5-lichnoe-priglashenie.md (там же таблица приглашённых) | N28: Составить список людей
A29: 26 | B29: 7. Чат | C29: Первое сообщение модератора в чате | D29: Чат | E29: Чат | F29: — | G29: — | H29: — | I29: — | J29: Нужно | K29: =IF(COUNTIF(F29:J29,"Нужно")=0,"Готово","Осталось: "&COUNTIF(F29:J29,"Нужно")) | L29: Готов | M29: telegram-chat/4-privetstvie.md
A30: 27 | B30: 8. YouTube | C30: Интро, переход и аутро — вставлять в каждый ролик | D30: Оформление | E30: YouTube | F30: — | G30: — | H30: — | I30: Нужно | J30: — | K30: =IF(COUNTIF(F30:J30,"Нужно")=0,"Готово","Осталось: "&COUNTIF(F30:J30,"Нужно")) | L30: Готов | M30: youtube/ (intro, stinger, outro + README) | N30: Не публикуются отдельно — используются при монтаже
A31: 28 | B31: 11. Неделя 27.10–02.11 | C31: Вт 27.10 · Зубр: «Вот такой вот спортбизнес, собачка» | D31: Картинка | E31: Зубр | F31: Нужно | G31: Нужно | H31: Нужно | I31: — | J31: — | K31: =IF(COUNTIF(F31:J31,"Нужно")=0,"Готово","Осталось: "&COUNTIF(F31:J31,"Нужно")) | L31: Нужно сделать | M31: content/nedelya-5_27.10-02.11/01-zubr-sportbiznes/ | N31: Сгенерировать зубра в спортзале (промпт в tekst.md)
A32: 29 | B32: 11. Неделя 27.10–02.11 | C32: Чт 29.10 · Схема зала «Места разбирают» + тарифы | D32: Картинка | E32: Продажа | F32: Нужно | G32: Нужно | H32: Нужно | I32: — | J32: — | K32: =IF(COUNTIF(F32:J32,"Нужно")=0,"Готово","Осталось: "&COUNTIF(F32:J32,"Нужно")) | L32: Готов | M32: content/nedelya-5_27.10-02.11/02-skhema-zala/ | N32: Подставить ссылки [ЧАТ] [ВК]
A33: 30 | B33: 11. Неделя 27.10–02.11 | C33: Сб 31.10 · Все спикеры в одном посте | D33: Картинка | E33: Спикеры | F33: Нужно | G33: Нужно | H33: Нужно | I33: — | J33: — | K33: =IF(COUNTIF(F33:J33,"Нужно")=0,"Готово","Осталось: "&COUNTIF(F33:J33,"Нужно")) | L33: Ждём цифры опроса | M33: content/nedelya-5_27.10-02.11/03-spikery-vmeste/ | N33: Кто есть кто на фото + данные 4 спикеров
A34: 31 | B34: 11. Неделя 27.10–02.11 | C34: Пн 02.11 · Рилс «До форума 11 дней» | D34: Рилс | E34: Отсчёт | F34: — | G34: Нужно | H34: Нужно | I34: — | J34: — | K34: =IF(COUNTIF(F34:J34,"Нужно")=0,"Готово","Осталось: "&COUNTIF(F34:J34,"Нужно")) | L34: Готов | M34: reels/bez-muzyki/reel6-otschet-11-dney-bez-zvuka.mp4 | N34: Трендовый трек в приложении
A35: 32 | B35: 10. Недели 3–4 | C35: Пн 12.10 · Рилс с зубром + карусель «9 форматов форума» | D35: Рилс + карусель | E35: Знакомство | F35: Нужно | G35: Нужно | H35: Нужно | I35: — | J35: — | K35: =IF(COUNTIF(F35:J35,"Нужно")=0,"Готово","Осталось: "&COUNTIF(F35:J35,"Нужно")) | L35: Готов | M35: content/nedeli-3-4_12.10-25.10/01-pn-12.10-zubr-formaty/ · reels/reel5-zubr-znakomtes.mp4
A36: 33 | B36: 10. Недели 3–4 | C36: Вт 13.10 · Сколько стоит потерянный клиент + чек-лист | D36: Карусель | E36: Польза | F36: Нужно | G36: Нужно | H36: Нужно | I36: — | J36: — | K36: =IF(COUNTIF(F36:J36,"Нужно")=0,"Готово","Осталось: "&COUNTIF(F36:J36,"Нужно")) | L36: Готов | M36: content/nedeli-3-4_12.10-25.10/02-vt-13.10-poteryannyy-klient/ | N36: Сразу после поста — чек-лист в Telegram
A37: 34 | B37: 10. Недели 3–4 | C37: Ср 14.10 · Розыгрыш билета (итоги 25.10) | D37: Карусель + сторис | E37: Розыгрыш | F37: Нужно | G37: Нужно | H37: Нужно | I37: — | J37: — | K37: =IF(COUNTIF(F37:J37,"Нужно")=0,"Готово","Осталось: "&COUNTIF(F37:J37,"Нужно")) | L37: Готов | M37: content/nedeli-3-4_12.10-25.10/03-sr-14.10-rozygrysh-bileta/ | N37: Записать выбор победителя
A38: 35 | B38: 10. Недели 3–4 | C38: Ср 14.10 · Мем «Родительский чат в 23:47» | D38: Мем | E38: Мем | F38: Нужно | G38: Нужно | H38: Нужно | I38: — | J38: — | K38: =IF(COUNTIF(F38:J38,"Нужно")=0,"Готово","Осталось: "&COUNTIF(F38:J38,"Нужно")) | L38: Готов | M38: content/nedeli-3-4_12.10-25.10/03-sr-14.10-mem-roditelskiy-chat/
A39: 36 | B39: 10. Недели 3–4 | C39: Чт 15.10 · 5 фраз, которые удерживают после пробного | D39: Карусель | E39: Польза | F39: Нужно | G39: Нужно | H39: Нужно | I39: — | J39: — | K39: =IF(COUNTIF(F39:J39,"Нужно")=0,"Готово","Осталось: "&COUNTIF(F39:J39,"Нужно")) | L39: Готов | M39: content/nedeli-3-4_12.10-25.10/04-cht-15.10-5-fraz-posle-probnogo/
A40: 37 | B40: 10. Недели 3–4 | C40: Пт 16.10 · Мем «Нет / Да» + рилс «Полный зал» | D40: Мем + рилс | E40: Мем | F40: Нужно | G40: Нужно | H40: Нужно | I40: — | J40: — | K40: =IF(COUNTIF(F40:J40,"Нужно")=0,"Готово","Осталось: "&COUNTIF(F40:J40,"Нужно")) | L40: Готов | M40: content/nedeli-3-4_12.10-25.10/05-pt-16.10-mem-net-da/ | N40: Рилс — под трендовый звук
...

Sheet Сводка
A1: Сводка по площадкам
A2: Площадка | B2: Запланировано | C2: Выложено | D2: Осталось | E2: Прогресс
A3: Telegram | B3: =COUNTIF(План!F4:F108,"Нужно")+COUNTIF(План!F4:F108,"Выложено") | C3: =COUNTIF(План!F4:F108,"Выложено") | D3: =B3-C3 | E3: =IF(B3=0,0,C3/B3)
A4: VK | B4: =COUNTIF(План!G4:G108,"Нужно")+COUNTIF(План!G4:G108,"Выложено") | C4: =COUNTIF(План!G4:G108,"Выложено") | D4: =B4-C4 | E4: =IF(B4=0,0,C4/B4)
A5: Instagram | B5: =COUNTIF(План!H4:H108,"Нужно")+COUNTIF(План!H4:H108,"Выложено") | C5: =COUNTIF(План!H4:H108,"Выложено") | D5: =B5-C5 | E5: =IF(B5=0,0,C5/B5)
A6: YouTube | B6: =COUNTIF(План!I4:I108,"Нужно")+COUNTIF(План!I4:I108,"Выложено") | C6: =COUNTIF(План!I4:I108,"Выложено") | D6: =B6-C6 | E6: =IF(B6=0,0,C6/B6)
A7: TG-чат | B7: =COUNTIF(План!J4:J108,"Нужно")+COUNTIF(План!J4:J108,"Выложено") | C7: =COUNTIF(План!J4:J108,"Выложено") | D7: =B7-C7 | E7: =IF(B7=0,0,C7/B7)
A8: Всего публикаций | B8: =SUM(B3:B7) | C8: =SUM(C3:C7) | D8: =B8-C8 | E8: =IF(B8=0,0,C8/B8)
A10: Пунктов плана | B10: =COUNTA(План!C4:C108)
A11: Готово целиком | B11: =COUNTIF(План!K4:K108,"Готово")
A12: Материал не готов (снять / сделать / цифры) | B12: =COUNTIF(План!L4:L108,"<>Готов")-COUNTBLANK(План!L4:L108)

Sheet Как пользоваться
A1: Как пользоваться таблицей
A2: 1. Идём по листу «План» сверху вниз — это рекомендуемый порядок. Даты не жёсткие: порядок можно менять, вырезав и вставив строку.
A3: 2. Колонки Telegram / VK / Instagram / YouTube / TG-чат: «Нужно» — надо выложить, «Выложено» — вышло, «—» — на этой площадке не публикуем. Значения выбираются из списка.
A4: 3. «Статус» считается сам: «Готово», когда на всех нужных площадках стоит «Выложено», иначе — сколько площадок осталось.
A5: 4. «Материал»: «Готов» — можно публиковать; «Нужно снять», «Нужно сделать», «Ждём цифры опроса» — подсвечено красным, сначала доделать.
A6: 5. Новый пункт — добавьте строку внизу и выберите значения из списков; на листе «Сводка» он учтётся автоматически.
A7: Пример строки: «Рилс «Полный зал» | Рилс | Атмосфера | Telegram: Нужно | VK: Выложено | Instagram: Выложено | YouTube: — | TG-чат: — | Материал: Готов».
